
Traceback (most recent call last):
  File "/home/h24/Desktop/python-app-deployment/python-fast-app/venv/lib/python3.12/site-packages/mysql/connector/network.py", line 600, in open_connection
    self.sock.connect(sockaddr)
OSError: [Errno 113] No route to host

The above exception was the direct cause of the following exception:

Traceback (most recent call last):
  File "/home/h24/Desktop/python-app-deployment/python-fast-app/venv/bin/uvicorn", line 8, in <module>
    sys.exit(main())
             ^^^^^^
  File "/home/h24/Desktop/python-app-deployment/python-fast-app/venv/lib/python3.12/site-packages/click/core.py", line 1130, in __call__
    return self.main(*args, **kwargs)
           ^^^^^^^^^^^^^^^^^^^^^^^^^^
  File "/home/h24/Desktop/python-app-deployment/python-fast-app/venv/lib/python3.12/site-packages/click/core.py", line 1055, in main
    rv = self.invoke(ctx)
         ^^^^^^^^^^^^^^^^
  File "/home/h24/Desktop/python-app-deployment/python-fast-app/venv/lib/python3.12/site-packages/click/core.py", line 1404, in invoke
    return ctx.invoke(self.callback, **ctx.params)
           ^^^^^^^^^^^^^^^^^^^^^^^^^^^^^^^^^^^^^^^
  File "/home/h24/Desktop/python-app-deployment/python-fast-app/venv/lib/python3.12/site-packages/click/core.py", line 760, in invoke
    return __callback(*args, **kwargs)
           ^^^^^^^^^^^^^^^^^^^^^^^^^^^
  File "/home/h24/Desktop/python-app-deployment/python-fast-app/venv/lib/python3.12/site-packages/uvicorn/main.py", line 410, in main
    run(
  File "/home/h24/Desktop/python-app-deployment/python-fast-app/venv/lib/python3.12/site-packages/uvicorn/main.py", line 578, in run
    server.run()
  File "/home/h24/Desktop/python-app-deployment/python-fast-app/venv/lib/python3.12/site-packages/uvicorn/server.py", line 61, in run
    return asyncio.run(self.serve(sockets=sockets))
           ^^^^^^^^^^^^^^^^^^^^^^^^^^^^^^^^^^^^^^^^
  File "/usr/lib/python3.12/asyncio/runners.py", line 194, in run
    return runner.run(main)
           ^^^^^^^^^^^^^^^^
  File "/usr/lib/python3.12/asyncio/runners.py", line 118, in run
    return self._loop.run_until_complete(task)
           ^^^^^^^^^^^^^^^^^^^^^^^^^^^^^^^^^^^
  File "/usr/lib/python3.12/asyncio/base_events.py", line 687, in run_until_complete
    return future.result()
           ^^^^^^^^^^^^^^^
  File "/home/h24/Desktop/python-app-deployment/python-fast-app/venv/lib/python3.12/site-packages/uvicorn/server.py", line 68, in serve
    config.load()
  File "/home/h24/Desktop/python-app-deployment/python-fast-app/venv/lib/python3.12/site-packages/uvicorn/config.py", line 473, in load
    self.loaded_app = import_from_string(self.app)
                      ^^^^^^^^^^^^^^^^^^^^^^^^^^^^
  File "/home/h24/Desktop/python-app-deployment/python-fast-app/venv/lib/python3.12/site-packages/uvicorn/importer.py", line 21, in import_from_string
    module = importlib.import_module(module_str)
             ^^^^^^^^^^^^^^^^^^^^^^^^^^^^^^^^^^^
  File "/usr/lib/python3.12/importlib/__init__.py", line 90, in import_module
    return _bootstrap._gcd_import(name[level:], package, level)
           ^^^^^^^^^^^^^^^^^^^^^^^^^^^^^^^^^^^^^^^^^^^^^^^^^^^^
  File "<frozen importlib._bootstrap>", line 1387, in _gcd_import
  File "<frozen importlib._bootstrap>", line 1360, in _find_and_load
  File "<frozen importlib._bootstrap>", line 1331, in _find_and_load_unlocked
  File "<frozen importlib._bootstrap>", line 935, in _load_unlocked
  File "<frozen importlib._bootstrap_external>", line 995, in exec_module
  File "<frozen importlib._bootstrap>", line 488, in _call_with_frames_removed
  File "/home/h24/Desktop/python-app-deployment/python-fast-app/main.py", line 3, in <module>
    from database import search_movies_by_year, upload_movie_data
  File "/home/h24/Desktop/python-app-deployment/python-fast-app/database.py", line 16, in <module>
    db_connection = mysql.connector.connect(**db_config)
                    ^^^^^^^^^^^^^^^^^^^^^^^^^^^^^^^^^^^^
  File "/home/h24/Desktop/python-app-deployment/python-fast-app/venv/lib/python3.12/site-packages/mysql/connector/pooling.py", line 294, in connect
    return MySQLConnection(*args, **kwargs)
           ^^^^^^^^^^^^^^^^^^^^^^^^^^^^^^^^
  File "/home/h24/Desktop/python-app-deployment/python-fast-app/venv/lib/python3.12/site-packages/mysql/connector/connection.py", line 164, in __init__
    self.connect(**kwargs)
  File "/home/h24/Desktop/python-app-deployment/python-fast-app/venv/lib/python3.12/site-packages/mysql/connector/abstracts.py", line 1181, in connect
    self._open_connection()
  File "/home/h24/Desktop/python-app-deployment/python-fast-app/venv/lib/python3.12/site-packages/mysql/connector/connection.py", line 570, in _open_connection
    self._socket.open_connection()
  File "/home/h24/Desktop/python-app-deployment/python-fast-app/venv/lib/python3.12/site-packages/mysql/connector/network.py", line 602, in open_connection
    raise InterfaceError(
mysql.connector.errors.InterfaceError: 2003: Can't connect to MySQL server on '192.168.0.250:3306' (113 No route to host)
Traceback (most recent call last):
  File "/home/h24/Desktop/python-app-deployment/python-fast-app/venv/lib/python3.12/site-packages/mysql/connector/network.py", line 600, in open_connection
    self.sock.connect(sockaddr)
OSError: [Errno 113] No route to host

The above exception was the direct cause of the following exception:

Traceback (most recent call last):
  File "/home/h24/Desktop/python-app-deployment/python-fast-app/venv/bin/uvicorn", line 8, in <module>
    sys.exit(main())
             ^^^^^^
  File "/home/h24/Desktop/python-app-deployment/python-fast-app/venv/lib/python3.12/site-packages/click/core.py", line 1130, in __call__
    return self.main(*args, **kwargs)
           ^^^^^^^^^^^^^^^^^^^^^^^^^^
  File "/home/h24/Desktop/python-app-deployment/python-fast-app/venv/lib/python3.12/site-packages/click/core.py", line 1055, in main
    rv = self.invoke(ctx)
         ^^^^^^^^^^^^^^^^
  File "/home/h24/Desktop/python-app-deployment/python-fast-app/venv/lib/python3.12/site-packages/click/core.py", line 1404, in invoke
    return ctx.invoke(self.callback, **ctx.params)
           ^^^^^^^^^^^^^^^^^^^^^^^^^^^^^^^^^^^^^^^
  File "/home/h24/Desktop/python-app-deployment/python-fast-app/venv/lib/python3.12/site-packages/click/core.py", line 760, in invoke
    return __callback(*args, **kwargs)
           ^^^^^^^^^^^^^^^^^^^^^^^^^^^
  File "/home/h24/Desktop/python-app-deployment/python-fast-app/venv/lib/python3.12/site-packages/uvicorn/main.py", line 410, in main
    run(
  File "/home/h24/Desktop/python-app-deployment/python-fast-app/venv/lib/python3.12/site-packages/uvicorn/main.py", line 578, in run
    server.run()
  File "/home/h24/Desktop/python-app-deployment/python-fast-app/venv/lib/python3.12/site-packages/uvicorn/server.py", line 61, in run
    return asyncio.run(self.serve(sockets=sockets))
           ^^^^^^^^^^^^^^^^^^^^^^^^^^^^^^^^^^^^^^^^
  File "/usr/lib/python3.12/asyncio/runners.py", line 194, in run
    return runner.run(main)
           ^^^^^^^^^^^^^^^^
  File "/usr/lib/python3.12/asyncio/runners.py", line 118, in run
    return self._loop.run_until_complete(task)
           ^^^^^^^^^^^^^^^^^^^^^^^^^^^^^^^^^^^
  File "/usr/lib/python3.12/asyncio/base_events.py", line 687, in run_until_complete
    return future.result()
           ^^^^^^^^^^^^^^^
  File "/home/h24/Desktop/python-app-deployment/python-fast-app/venv/lib/python3.12/site-packages/uvicorn/server.py", line 68, in serve
    config.load()
  File "/home/h24/Desktop/python-app-deployment/python-fast-app/venv/lib/python3.12/site-packages/uvicorn/config.py", line 473, in load
    self.loaded_app = import_from_string(self.app)
                      ^^^^^^^^^^^^^^^^^^^^^^^^^^^^
  File "/home/h24/Desktop/python-app-deployment/python-fast-app/venv/lib/python3.12/site-packages/uvicorn/importer.py", line 21, in import_from_string
    module = importlib.import_module(module_str)
             ^^^^^^^^^^^^^^^^^^^^^^^^^^^^^^^^^^^
  File "/usr/lib/python3.12/importlib/__init__.py", line 90, in import_module
    return _bootstrap._gcd_import(name[level:], package, level)
           ^^^^^^^^^^^^^^^^^^^^^^^^^^^^^^^^^^^^^^^^^^^^^^^^^^^^
  File "<frozen importlib._bootstrap>", line 1387, in _gcd_import
  File "<frozen importlib._bootstrap>", line 1360, in _find_and_load
  File "<frozen importlib._bootstrap>", line 1331, in _find_and_load_unlocked
  File "<frozen importlib._bootstrap>", line 935, in _load_unlocked
  File "<frozen importlib._bootstrap_external>", line 995, in exec_module
  File "<frozen importlib._bootstrap>", line 488, in _call_with_frames_removed
  File "/home/h24/Desktop/Start/python-fast-app/main.py", line 3, in <module>
    from database import search_movies_by_year, upload_movie_data
  File "/home/h24/Desktop/Start/python-fast-app/database.py", line 16, in <module>
    db_connection = mysql.connector.connect(**db_config)
                    ^^^^^^^^^^^^^^^^^^^^^^^^^^^^^^^^^^^^
  File "/home/h24/Desktop/python-app-deployment/python-fast-app/venv/lib/python3.12/site-packages/mysql/connector/pooling.py", line 294, in connect
    return MySQLConnection(*args, **kwargs)
           ^^^^^^^^^^^^^^^^^^^^^^^^^^^^^^^^
  File "/home/h24/Desktop/python-app-deployment/python-fast-app/venv/lib/python3.12/site-packages/mysql/connector/connection.py", line 164, in __init__
    self.connect(**kwargs)
  File "/home/h24/Desktop/python-app-deployment/python-fast-app/venv/lib/python3.12/site-packages/mysql/connector/abstracts.py", line 1181, in connect
    self._open_connection()
  File "/home/h24/Desktop/python-app-deployment/python-fast-app/venv/lib/python3.12/site-packages/mysql/connector/connection.py", line 570, in _open_connection
    self._socket.open_connection()
  File "/home/h24/Desktop/python-app-deployment/python-fast-app/venv/lib/python3.12/site-packages/mysql/connector/network.py", line 602, in open_connection
    raise InterfaceError(
mysql.connector.errors.InterfaceError: 2003: Can't connect to MySQL server on '192.168.0.250:3306' (113 No route to host)
